[2024-09-27 14:59:20 +0200] [108117] [INFO] Starting gunicorn 23.0.0
[2024-09-27 14:59:20 +0200] [108117] [ERROR] Connection in use: ('::', 8793)
[2024-09-27 14:59:20 +0200] [108117] [ERROR] connection to ('::', 8793) failed: [Errno 98] Address already in use
[2024-09-27 14:59:21 +0200] [108117] [ERROR] Connection in use: ('::', 8793)
[2024-09-27 14:59:21 +0200] [108117] [ERROR] connection to ('::', 8793) failed: [Errno 98] Address already in use
[2024-09-27 14:59:22 +0200] [108117] [ERROR] Connection in use: ('::', 8793)
[2024-09-27 14:59:22 +0200] [108117] [ERROR] connection to ('::', 8793) failed: [Errno 98] Address already in use
[2024-09-27 14:59:23 +0200] [108117] [ERROR] Connection in use: ('::', 8793)
[2024-09-27 14:59:23 +0200] [108117] [ERROR] connection to ('::', 8793) failed: [Errno 98] Address already in use
[2024-09-27 14:59:24 +0200] [108117] [ERROR] Connection in use: ('::', 8793)
[2024-09-27 14:59:24 +0200] [108117] [ERROR] connection to ('::', 8793) failed: [Errno 98] Address already in use
[2024-09-27 14:59:25 +0200] [108117] [ERROR] Can't connect to ('::', 8793)
Process ForkProcess-2:
Traceback (most recent call last):
  File "/home/isi/miniconda3/envs/clean_env/lib/python3.10/site-packages/sqlalchemy/engine/base.py", line 1910, in _execute_context
    self.dialect.do_execute(
  File "/home/isi/miniconda3/envs/clean_env/lib/python3.10/site-packages/sqlalchemy/engine/default.py", line 736, in do_execute
    cursor.execute(statement, parameters)
sqlite3.OperationalError: no such table: dag_warning

The above exception was the direct cause of the following exception:

Traceback (most recent call last):
  File "/home/isi/miniconda3/envs/clean_env/lib/python3.10/multiprocessing/process.py", line 314, in _bootstrap
    self.run()
  File "/home/isi/miniconda3/envs/clean_env/lib/python3.10/multiprocessing/process.py", line 108, in run
    self._target(*self._args, **self._kwargs)
  File "/home/isi/miniconda3/envs/clean_env/lib/python3.10/site-packages/airflow/dag_processing/manager.py", line 247, in _run_processor_manager
    processor_manager.start()
  File "/home/isi/miniconda3/envs/clean_env/lib/python3.10/site-packages/airflow/dag_processing/manager.py", line 489, in start
    return self._run_parsing_loop()
  File "/home/isi/miniconda3/envs/clean_env/lib/python3.10/site-packages/airflow/dag_processing/manager.py", line 626, in _run_parsing_loop
    DagWarning.purge_inactive_dag_warnings()
  File "/home/isi/miniconda3/envs/clean_env/lib/python3.10/site-packages/airflow/api_internal/internal_api_call.py", line 139, in wrapper
    return func(*args, **kwargs)
  File "/home/isi/miniconda3/envs/clean_env/lib/python3.10/site-packages/airflow/utils/session.py", line 97, in wrapper
    return func(*args, session=session, **kwargs)
  File "/home/isi/miniconda3/envs/clean_env/lib/python3.10/site-packages/airflow/models/dagwarning.py", line 82, in purge_inactive_dag_warnings
    cls._purge_inactive_dag_warnings_with_retry(session)
  File "/home/isi/miniconda3/envs/clean_env/lib/python3.10/site-packages/airflow/utils/retries.py", line 93, in wrapped_function
    for attempt in run_with_db_retries(max_retries=retries, logger=logger, **retry_kwargs):
  File "/home/isi/miniconda3/envs/clean_env/lib/python3.10/site-packages/tenacity/__init__.py", line 443, in __iter__
    do = self.iter(retry_state=retry_state)
  File "/home/isi/miniconda3/envs/clean_env/lib/python3.10/site-packages/tenacity/__init__.py", line 376, in iter
    result = action(retry_state)
  File "/home/isi/miniconda3/envs/clean_env/lib/python3.10/site-packages/tenacity/__init__.py", line 418, in exc_check
    raise retry_exc.reraise()
  File "/home/isi/miniconda3/envs/clean_env/lib/python3.10/site-packages/tenacity/__init__.py", line 185, in reraise
    raise self.last_attempt.result()
  File "/home/isi/miniconda3/envs/clean_env/lib/python3.10/concurrent/futures/_base.py", line 451, in result
    return self.__get_result()
  File "/home/isi/miniconda3/envs/clean_env/lib/python3.10/concurrent/futures/_base.py", line 403, in __get_result
    raise self._exception
  File "/home/isi/miniconda3/envs/clean_env/lib/python3.10/site-packages/airflow/utils/retries.py", line 102, in wrapped_function
    return func(*args, **kwargs)
  File "/home/isi/miniconda3/envs/clean_env/lib/python3.10/site-packages/airflow/models/dagwarning.py", line 95, in _purge_inactive_dag_warnings_with_retry
    session.execute(query.execution_options(synchronize_session=False))
  File "/home/isi/miniconda3/envs/clean_env/lib/python3.10/site-packages/sqlalchemy/orm/session.py", line 1717, in execute
    result = conn._execute_20(statement, params or {}, execution_options)
  File "/home/isi/miniconda3/envs/clean_env/lib/python3.10/site-packages/sqlalchemy/engine/base.py", line 1710, in _execute_20
    return meth(self, args_10style, kwargs_10style, execution_options)
  File "/home/isi/miniconda3/envs/clean_env/lib/python3.10/site-packages/sqlalchemy/sql/elements.py", line 334, in _execute_on_connection
    return connection._execute_clauseelement(
  File "/home/isi/miniconda3/envs/clean_env/lib/python3.10/site-packages/sqlalchemy/engine/base.py", line 1577, in _execute_clauseelement
    ret = self._execute_context(
  File "/home/isi/miniconda3/envs/clean_env/lib/python3.10/site-packages/sqlalchemy/engine/base.py", line 1953, in _execute_context
    self._handle_dbapi_exception(
  File "/home/isi/miniconda3/envs/clean_env/lib/python3.10/site-packages/sqlalchemy/engine/base.py", line 2134, in _handle_dbapi_exception
    util.raise_(
  File "/home/isi/miniconda3/envs/clean_env/lib/python3.10/site-packages/sqlalchemy/util/compat.py", line 211, in raise_
    raise exception
  File "/home/isi/miniconda3/envs/clean_env/lib/python3.10/site-packages/sqlalchemy/engine/base.py", line 1910, in _execute_context
    self.dialect.do_execute(
  File "/home/isi/miniconda3/envs/clean_env/lib/python3.10/site-packages/sqlalchemy/engine/default.py", line 736, in do_execute
    cursor.execute(statement, parameters)
sqlalchemy.exc.OperationalError: (sqlite3.OperationalError) no such table: dag_warning
[SQL: DELETE FROM dag_warning WHERE dag_warning.dag_id IN (SELECT dag.dag_id 
FROM dag 
WHERE dag.is_active = 0)]
(Background on this error at: https://sqlalche.me/e/14/e3q8)
